Workbook
Name CriticalThreshold: MatrixImpact!$G$2
Name LastRMC: Header!$D$20
Name LogarithmBase: MatrixImpact!$G$3
Name NbObjectives: Objectives!$G$8
Name ReportingPeriod: Parameters!$E$10
Name ReportingUnits: Parameters!$A$2:$C$5
Name RiskIdBeginsWith: Parameters!$A$2
Name SelectedBU: Header!$H$10
Name Timeframe: Parameters!$E$3:$E$8
Name timehorizon: Parameters!$E$13:$E$15
Name ValidationDate: Header!$D$14

Sheet 7-Instructions
A1: CORE v7 INTEGRATED RISK & OPPORTUNITY MANAGEMENT — USER GUIDE
A40: INTEGRATED WORKFLOW (v7)
A41: Step 1: | B41: Complete Calibration (org profile dropdowns). All CORE coefficients auto-calculate.
A42: Step 2: | B42: Complete Company_RI and Company_SMI (sub-component scores 0-10).
A43: Step 3: | B43: Enter risks in Top 10 Risks sheet (ID, Title, Causes, Impact 1-5, Likelihood 1-5, Trend).
A44: Step 4: | B44: RADAR auto-populates from Top 10 Risks with full CORE calculation chain.
A45: Step 5: | B45: Complete Risk Control sheet (ownership, limits, assessment, controls, monitoring).
A46: Step 6: | B46: FORGE Decision Quality auto-calculates from Risk Control. RE, Containment, R-TTS follow.
A47: Step 7: | B47: Enter FORGE Severity (1-10) per crisis for R-TTS and Urgency Index to compute.
A48: Step 8: | B48: Complete Risk Interaction Map. Coherence Density and Von Neumann Entropy auto-update.
A49: Step 9: | B49: Enter opportunities in Opportunities sheet. Review Dashboard for integrated view.

Sheet Header
E3: Risk Management Reporting
E5: Select:
E6: Emerging Risk Assessment (RADAR) | I6: =TRUE() -> TRUE
E7: Enterprise Risk Assessment (FORGE) | I7: =FALSE() -> FALSE
C10: Reporting Unit: | H10: 3
C12: Reporting Period: | D12: 2 | F12: To be filled in by Corporate Risk Management:
C14: Validation Date: | F14: Review Date:
C16: CEO: | F16: Reviewer: | H16: 1
C18: RM Contact:
H19: Please send this report to:
C20: Last Risk Management meeting:

Sheet Calibration
A1: CORE v6.0 — Organizational Calibration System | G1: User input
A2: Select characteristics → coefficients auto-calculate
H3: To be selected
A4: SECTION A: PRIMARY ORGANIZATIONAL PROFILE | H4: Calculated
A5: Characteristic | B5: Selection | C5: Weight | D5: Impact | E5: Description | H5: Linked to cell
A6: Industry Sector | B6: Manufacturing | C6: 0.25 | E6: Primary classification
A7: Company Maturity | B7: Established (>10 years) | C7: 0.2 | E7: Lifecycle stage
A8: Risk Appetite | B8: Moderate | C8: 0.2 | E8: Conservative/Moderate/Aggressive
A9: Geographic Scope | B9: Multi-National | C9: 0.15 | E9: Market footprint
A10: Regulatory Environment | B10: Heavy | C10: 0.1 | E10: Regulatory intensity
A11: Digital Maturity | B11: Advanced | C11: 0.1 | E11: Technology integration
A14: SECTION B: DERIVED COEFFICIENTS
A15: Coefficient | B15: Symbol | C15: Value | D15: Range | E15: Used In
A16: Velocity Multiplier | B16: α | C16: =ROUND(0.5+1.5*(C6*IF(B6="Financial Services",0.9,IF(B6="Technology",0.85,IF(B6="Healthcare",0.55,IF(B6="Manufacturing",0.4,IF(B6="Energy",0.35,IF(B6="Retail",0.5,0.3))))))+C9*IF(B9="Global",0.8,IF(B9="Multi-National",0.6,IF(B9="Regional",0.35,0.15)))+C7*IF(B7="Startup (<3 years)",0.8,IF(B7="Growth (3-10 years)",0.6,IF(B7="Established (>10 years)",0.4,0.25))))/(C6+C9+C7),2) -> 1.18 | D16: 0.5–2.0 | E16: TTS, EW-TTS
A17: Impact Scaling | B17: β | C17: =ROUND(0.5+1*(C10*IF(B10="Extreme",0.9,IF(B10="Heavy",0.7,IF(B10="Moderate",0.45,0.2)))+C7*IF(B7="Legacy (>50 years)",0.8,IF(B7="Established (>10 years)",0.6,IF(B7="Growth (3-10 years)",0.35,0.2)))+C6*IF(B6="Financial Services",0.8,IF(B6="Technology",0.6,IF(B6="Healthcare",0.7,IF(B6="Manufacturing",0.5,IF(B6="Energy",0.7,IF(B6="Retail",0.4,0.8)))))))/(C10+C7+C6),2) -> 1.07 | D17: 0.5–1.5 | E17: Normalization
A18: Phase Proximity Base | B18: Φ₀ | C18: =ROUND(0.3+0.5*(C7*IF(B7="Startup (<3 years)",0.85,IF(B7="Growth (3-10 years)",0.65,IF(B7="Established (>10 years)",0.4,0.3)))+C6*IF(B6="Financial Services",0.75,IF(B6="Technology",0.7,IF(B6="Healthcare",0.5,IF(B6="Manufacturing",0.4,IF(B6="Energy",0.5,IF(B6="Retail",0.5,0.35))))))+C11*IF(B11="Basic",0.6,IF(B11="Intermediate",0.45,IF(B11="Advanced",0.35,0.3))))/(C7+C6+C11),2) -> 0.5 | D18: 0.3–0.8 | E18: EW-TTS
A19: Coherence Decay | B19: λ_c | C19: =ROUND(C9*IF(B9="Global",0.02,IF(B9="Multi-National",0.05,IF(B9="Regional",0.1,0.16)))+C6*IF(B6="Financial Services",0.03,IF(B6="Technology",0.05,IF(B6="Healthcare",0.08,IF(B6="Manufacturing",0.1,IF(B6="Energy",0.07,IF(B6="Retail",0.12,0.09))))))+C10*IF(B10="Extreme",0.04,IF(B10="Heavy",0.06,IF(B10="Moderate",0.1,0.15))),3) -> 0.039 | D19: 0.01–0.20 | E19: Density Matrix
A20: Palmer Noise Base | B20: η₀ | C20: =ROUND(C11*IF(B11="Basic",0.28,IF(B11="Intermediate",0.2,IF(B11="Advanced",0.13,0.08)))+C6*IF(B6="Financial Services",0.12,IF(B6="Technology",0.1,IF(B6="Healthcare",0.18,IF(B6="Manufacturing",0.2,IF(B6="Energy",0.22,IF(B6="Retail",0.15,0.16))))))+C8*IF(B8="Conservative",0.2,IF(B8="Moderate",0.15,0.1)),3) -> 0.093 | D20: 0.05–0.30 | E20: Stochastic resonance
A21: Max Velocity | B21: v_max | C21: =ROUND((C6+C11)*IF(B6="Financial Services",10,IF(B6="Technology",9,IF(B6="Healthcare",7,IF(B6="Manufacturing",6,IF(B6="Energy",5,IF(B6="Retail",7,4))))))/(C6+C11)+C11*IF(B11="Digital-Native",1.5,IF(B11="Advanced",0.8,IF(B11="Intermediate",0.3,0)))/(C6+C11),1) -> 6.2 | D21: 3–10 | E21: Lorentz Factor
A22: Conformal Boundary CCORD | B22: S | C22: 1 | D22: 0.5–2.0 | E22: |x|+|t|≤S
A23: Risk Appetite Factor | B23: RAF | C23: =IF(B8="Conservative",0.3,IF(B8="Moderate",0.5,0.8)) -> 0.5 | D23: 0.1–0.9 | E23: Zone thresholds
A24: MC Simulation Runs | B24: N_MC | C24: 50 | D24: 10–1000 | E24: Ensemble size
A25: Confidence Level | B25: CL | C25: 0.95 | D25: 0.80–0.99 | E25: VaR percentile
A26: Conformal Time Scale | B26: κ_t | C26: =ROUND(1.5+1.5*(C6*IF(B6="Financial Services",0.8,IF(B6="Technology",0.7,IF(B6="Healthcare",0.4,IF(B6="Manufacturing",0.3,IF(B6="Energy",0.3,IF(B6="Retail",0.5,0.2))))))+C8*IF(B8="Aggressive",0.7,IF(B8="Moderate",0.4,0.2)))/(C6+C8),2) -> 2.02 | D26: 1.5–3.0 | E26: TANH compression
A28: SECTION C: RISK CATEGORIES
A29: Category | B29: Code | C29: RADAR Scope | D29: FORGE Scope | E29: Opportunity Scope
A30: Operational | B30: OPS | C30: Process failures, supply chain | D30: Safety recalls, shutdowns | E30: Process optimization
A31: Technology | B31: TECH | C31: Cyber threats, system failures | D31: Data breaches, IT outages | E31: Digital transformation
A32: Regulatory | B32: REG | C32: Emerging regulation | D32: Enforcement actions | E32: Regulatory arbitrage
A33: Strategic | B33: STR | C33: Market shifts, competition | D33: Partnership collapse | E33: M&A, consolidation
A34: Financial | B34: FIN | C34: Currency, credit, liquidity | D34: Insolvency, margin calls | E34: Capital deployment
A35: ESG | B35: ESG | C35: Climate, social, governance | D35: Environmental contamination | E35: Sustainability leadership
A36: Geopolitical | B36: GEO | C36: Trade tensions, sanctions | D36: Asset seizure, conflict | E36: Geographic diversification
A37: Reputational | B37: REP | C37: Brand erosion, media | D37: Crisis communications | E37: Brand strengthening
A40: SECTION D: DROPDOWN SCALE DEFINITIONS
A41: Scale | B41: Values | C41: Sheet | D41: Type | E41: Notes
A42: Velocity (1-10) | B42: 1=Glacial → 10=Instant | C42: RADAR | D42: Input | E42: Propagation speed
A43: Severity (1-10) | B43: 1=Negligible → 10=Catastrophic | C43: FORGE | D43: Input | E43: Crisis severity
A44: Strategic Fit (1-10) | B44: 1=Misaligned → 10=Perfect | C44: Opportunities | D44: Input | E44: Alignment
A45: Phase Proximity (0-1) | B45: 0=Distant → 1=Crystallized | C45: RADAR | D45: Input | E45: Temporal proximity
...

Sheet CORE
A1: CORE v6.0 — Master Framework
A2: Horizon Event Risk Opportunity Dynamics — Company-Level Properties
A4: GLOBAL PARAMETERS
A5: Parameter | B5: Value | C5: Unit | D5: Min | E5: Max | F5: Default | G5: Notes
A6: Company Name | B6: Hypothetical Corp | G6: Entity under analysis
A7: Analysis Date | B7: 2026-03-04 | G7: Assessment date
A8: Max Impact Exposure | B8: 1000 | C8: €M | D8: 1 | E8: 10000 | F8: 1000 | G8: Upper bound for normalization
A9: Confidence Level | B9: 0.95 | D9: 0.8 | E9: 0.99 | F9: 0.95 | G9: MC VaR percentile
A10: Simulation Runs | B10: 50 | D10: 10 | E10: 1000 | F10: 50 | G10: MC ensemble size
A11: Palmer Noise | B11: =Calibration!C20 -> 0.093 | D11: 0 | E11: 0.5 | F11: 0.15 | G11: Stochastic resonance
A12: Phase Prox Threshold | B12: 0.7 | D12: 0 | E12: 1 | F12: 0.7 | G12: EW-TTS activation
A13: Coherence Decay | B13: =Calibration!C19 -> 0.039 | D13: 0 | E13: 0.2 | F13: 0.05 | G13: λ temporal decay
A14: Conformal Boundary S | B14: 1 | D14: 0.5 | E14: 2 | F14: 1 | G14: |x|+|t|≤S
A15: Max Velocity | B15: =Calibration!C21 -> 6.2 | D15: 3 | E15: 10 | F15: 8 | G15: Lorentz denominator
A16: Risk Appetite | B16: =Calibration!C23 -> 0.5 | D16: 0.1 | E16: 0.9 | F16: 0.5 | G16: Zone thresholds
A19: IMPACT NORMALIZATION (€M → Score 0-10)
A20: Formula: | B20: MIN(20, MAX(1, 2×LN(Impact_€M + 1)))
A21: €M | B21: Score | C21: Interpretation
A22: 0.5 | B22: =MIN(20,MAX(1,2*LN(A22+1))) -> 1 | C22: Minimal
A23: 5 | B23: =MIN(20,MAX(1,2*LN(A23+1))) -> 3.5835189 | C23: Low
A24: 25 | B24: =MIN(20,MAX(1,2*LN(A24+1))) -> 6.5161931 | C24: Moderate
A25: 100 | B25: =MIN(20,MAX(1,2*LN(A25+1))) -> 9.230241 | C25: Major
A26: 500 | B26: =MIN(20,MAX(1,2*LN(A26+1))) -> 12.433212 | C26: Critical
A27: 1000 | B27: =MIN(20,MAX(1,2*LN(A27+1))) -> 13.81751 | C27: Catastrophic
A28: 2000 | B28: =MIN(20,MAX(1,2*LN(A28+1))) -> 15.202805 | C28: Maximum
A30: RESILIENCE INDEX (RI) — from Company_RI
A31: Component | B31: Weight | C31: Score | D31: Weighted
A32: Control Effectiveness | B32: 0.35 | C32: =Company_RI!D10 -> 7.2 | D32: =B32*C32 -> 2.52
A33: Recovery Capability | B33: 0.25 | C33: =Company_RI!D11 -> 6.5 | D33: =B33*C33 -> 1.625
A34: Resource Adequacy | B34: 0.2 | C34: =Company_RI!D12 -> 7.8 | D34: =B34*C34 -> 1.56
A35: Adaptive Capacity | B35: 0.2 | C35: =Company_RI!D13 -> 5.9 | D35: =B35*C35 -> 1.18
A36: RESILIENCE INDEX (RI) | D36: =SUM(D32:D35) -> 6.885 | F36: Scale: 0-10
A38: STRATEGIC MOBILITY INDEX (SMI) — from Company_SMI
A39: Component | B39: Weight | C39: Score | D39: Weighted
A40: Market Positioning | B40: 0.3 | C40: =Company_SMI!D10 -> 6.8 | D40: =B40*C40 -> 2.04
A41: Strategic Capital | B41: 0.3 | C41: =Company_SMI!D11 -> 7.1 | D41: =B41*C41 -> 2.13
A42: Innovation Capability | B42: 0.25 | C42: =Company_SMI!D12 -> 5.5 | D42: =B42*C42 -> 1.375
A43: Strategic Flexibility | B43: 0.15 | C43: =Company_SMI!D13 -> 6.2 | D43: =B43*C43 -> 0.93
A44: STRATEGIC MOBILITY INDEX (SMI) | D44: =SUM(D40:D43) -> 6.475 | F44: Scale: 0-10
A46: RI–SMI DUALITY DIAGNOSTIC
...

Sheet Company_RI
A1: Resilience Index (RI) — Detailed Calculation
A2: Potential Energy | Empirical: 8-crisis analysis | Feeds FORGE
A4: SECTION A: CRISIS-FREQUENCY WEIGHT DERIVATION
A5: Crisis | B5: Year | C5: CE? | D5: RC? | E5: RA? | F5: AC? | G5: Primary Cause
A6: ENRON | B6: 2001 | C6: 1 | D6: 0 | E6: 0 | F6: 1 | G6: Control collapse
A7: 2008 Financial | B7: 2008 | C7: 1 | D7: 1 | E7: 1 | F7: 0 | G7: Systemic control+resource
A8: Deepwater Horizon | B8: 2010 | C8: 1 | D8: 1 | E8: 0 | F8: 0 | G8: Safety control+recovery
A9: Boeing MAX | B9: 2019 | C9: 1 | D9: 0 | E9: 0 | F9: 1 | G9: Design control+adaptive
A10: COVID-19 | B10: 2020 | C10: 0 | D10: =F20 -> 7.2 | E10: 1 | F10: 1 | G10: Recovery+resource+adaptation
A11: SVB | B11: 2023 | C11: 1 | D11: =F21 -> 6.5 | E11: 1 | F11: 0 | G11: Risk control+liquidity
A12: Wirecard | B12: 2020 | C12: 1 | D12: =F22 -> 7.8 | E12: 0 | F12: 0 | G12: Fundamental control fraud
A13: Credit Suisse | B13: 2023 | C13: 1 | D13: =F23 -> 5.9 | E13: 1 | F13: 1 | G13: All dimensions
A14: FREQUENCY | C14: =SUM(C6:C13) -> 7 | D14: =SUM(D6:D13) -> 29.4 | E14: =SUM(E6:E13) -> 4 | F14: =SUM(F6:F13) -> 4
A15: WEIGHT | C15: =C14/SUM(C14:F14) -> 0.15765766 | D15: =D14/SUM(C14:F14) -> 0.66216216 | E15: =E14/SUM(C14:F14) -> 0.09009009 | F15: =F14/SUM(C14:F14) -> 0.09009009
A16: APPLIED | C16: 0.35 | D16: 0.25 | E16: 0.2 | F16: 0.2 | G16: Rounded
A18: SECTION B: COMPONENT SCORING
A19: Component | B19: Weight | C19: Sub-1 | D19: Sub-2 | E19: Sub-3 | F19: Score (0-10) | G19: Method
A20: Control Effectiveness | B20: =CORE!B32 -> 0.35 | C20: Audit score | D20: Process maturity | E20: Compliance rate | F20: 7.2 | G20: Avg 3 sub-metrics
A21: Recovery Capability | B21: =CORE!B33 -> 0.25 | C21: RTO achievement | D21: BCP test success | E21: Backup coverage | F21: 6.5 | G21: Recovery performance
A22: Resource Adequacy | B22: =CORE!B34 -> 0.2 | C22: Cash/revenue | D22: Insurance coverage | E22: Credit headroom | F22: 7.8 | G22: Financial buffer
A23: Adaptive Capacity | B23: =CORE!B35 -> 0.2 | C23: Learning rate | D23: Pivot speed | E23: Scenario depth | F23: 5.9 | G23: Change responsiveness
A25: RESILIENCE INDEX (RI) | F25: =SUMPRODUCT(B20:B23,F20:F23) -> 6.885
A27: SECTION C: RI-DERIVED PARAMETERS (→ FORGE)
A28: Parameter | B28: Symbol | C28: Formula | D28: Value | E28: Used In
A29: Containment Index | B29: CI | C29: RI/10 | D29: =F25/10 -> 0.6885 | E29: FORGE R-TTS
A30: Palmer Noise B | B30: η_B | C30: 0.1+0.3×(1-CI) | D30: =0.1+0.3*(1-D29) -> 0.19345 | E30: FORGE MC
A31: R-TTS Decay Rate | B31: λ | C31: RI/180 | D31: =F25/180 -> 0.03825 | E31: FORGE recovery
A32: Recovery Modifier | B32: R_mod | C32: 1+(1-RI/10) | D32: =1+(1-F25/10) -> 1.3115 | E32: FORGE time
A35: SECTION D: IMPROVEMENT LEVER SENSITIVITY
A36: Component | B36: Current | C36: RI if +1pt | D36: RI Δ | E36: Weight | F36: Δ/Weight | G36: Priority
A37: Control Effectiveness | B37: =F20 -> 7.2 | C37: =F25+B20*1 -> 7.235 | D37: =C37-F25 -> 0.35 | E37: 0.35 | F37: =D37/E37 -> 1 | G37: =IF(D37>0.3,"HIGH",IF(D37>0.2,"MODERATE","LOW")) -> HIGH
A38: Recovery Capability | B38: =F21 -> 6.5 | C38: =F25+B21*1 -> 7.135 | D38: =C38-F25 -> 0.25 | E38: 0.25 | F38: =D38/E38 -> 1 | G38: =IF(D38>0.3,"HIGH",IF(D38>0.2,"MODERATE","LOW")) -> MODERATE
A39: Resource Adequacy | B39: =F22 -> 7.8 | C39: =F25+B22*1 -> 7.085 | D39: =C39-F25 -> 0.2 | E39: 0.2 | F39: =D39/E39 -> 1 | G39: =IF(D39>0.3,"HIGH",IF(D39>0.2,"MODERATE","LOW")) -> LOW
A40: Adaptive Capacity | B40: =F23 -> 5.9 | C40: =F25+B23*1 -> 7.085 | D40: =C40-F25 -> 0.2 | E40: 0.2 | F40: =D40/E40 -> 1 | G40: =IF(D40>0.3,"HIGH",IF(D40>0.2,"MODERATE","LOW")) -> LOW

Sheet Company_SMI
A1: Strategic Mobility Index (SMI) — Detailed Calculation
A2: Kinetic Energy | Empirical: 5 opportunity-capture cases | Feeds Opportunities
A4: SECTION A: OPPORTUNITY-CAPTURE WEIGHT DERIVATION
A5: Case | B5: Year | C5: MP? | D5: SC? | E5: IC? | F5: SF? | G5: Mechanism
A6: Goldman 2008 | B6: 2008 | C6: 1 | D6: 1 | E6: 0 | F6: 1 | G6: Position+capital
A7: Apple iPhone | B7: 2007 | C7: 1 | D7: 1 | E7: 1 | F7: 0 | G7: Vision+R&D+execution
A8: Tesla EV | B8: 2015 | C8: 1 | D8: 0 | E8: 1 | F8: 1 | G8: Position+innovation
A9: Zoom COVID | B9: 2020 | C9: 0 | D9: 1 | E9: 1 | F9: 1 | G9: Capital+speed+flex
A10: NVIDIA AI | B10: 2023 | C10: 1 | D10: =F17 -> 6.8 | E10: 1 | F10: 0 | G10: Position+capital+innov
A11: FREQUENCY | C11: =SUM(C6:C10) -> 4 | D11: =F18 -> 7.1 | E11: =SUM(E6:E10) -> 4 | F11: =SUM(F6:F10) -> 3
A12: WEIGHT | C12: =C11/SUM(C11:F11) -> 0.22099448 | D12: =F19 -> 5.5 | E12: =E11/SUM(C11:F11) -> 0.22099448 | F12: =F11/SUM(C11:F11) -> 0.16574586
A13: APPLIED | C13: 0.3 | D13: =F20 -> 6.2 | E13: 0.25 | F13: 0.15 | G13: Symmetric MP-SC
A15: SECTION B: COMPONENT SCORING
A16: Component | B16: Weight | C16: Sub-1 | D16: Sub-2 | E16: Sub-3 | F16: Score | G16: Method
A17: Market Positioning | B17: 0.3 | C17: Market share trend | D17: Brand strength | E17: Distribution reach | F17: 6.8 | G17: Competitive composite
A18: Strategic Capital | B18: 0.3 | C18: R&D spend ratio | D18: Talent pipeline | E18: IP portfolio | F18: 7.1 | G18: Investment index
A19: Innovation Capability | B19: 0.25 | C19: Time-to-market | D19: Prototype velocity | E19: Digital maturity | F19: 5.5 | G19: Innovation pipeline
A20: Strategic Flexibility | B20: 0.15 | C20: Pivot speed | D20: Legacy constraints | E20: Decision cycle | F20: 6.2 | G20: Agility measure
A22: STRATEGIC MOBILITY INDEX (SMI) | F22: =SUMPRODUCT(B17:B20,F17:F20) -> 6.475
A24: SECTION C: SMI-DERIVED PARAMETERS (→ Opportunities)
A25: Parameter | B25: Symbol | C25: Formula | D25: Value | E25: Used In
A26: OTS Amplification | B26: A_OTS | C26: 1+SMI×0.05 | D26: =1+F22*0.05 -> 1.32375 | E26: Capture multiplier
A27: Palmer Noise Opp | B27: η_O | C27: 0.1+0.3×(1-SMI/10) | D27: =0.1+0.3*(1-F22/10) -> 0.20575 | E27: Opp MC
A28: Capture Velocity | B28: v_cap | C28: SMI/10 | D28: =F22/10 -> 0.6475 | E28: Capture speed
A29: Momentum | B29: p | C29: SMI×v_cap | D29: =F22*(F22/10) -> 4.1925625 | E29: Mass×velocity
A32: SECTION D: BLACK PHOENIX MATRIX
A33: Current RI: | B33: =CORE!D36 -> 6.885 | C33: Current SMI: | D33: =F22 -> 6.475 | E33: Posture: | F33: =CORE!B53 -> BLACK PHOENIX
A35: Quadrant | B35: RI | C35: SMI | D35: Description | E35: Example | F35: Strategy
A36: BLACK PHOENIX | B36: ≥5.5 | C36: ≥5.5 | D36: High resilience + high mobility | E36: Apple post-2007 | F36: Maintain and exploit
A37: INCUMBENT DEFENDER | B37: ≥5.5 | C37: <5.5 | D37: Strong defense, weak offense | E37: IBM pre-cloud | F37: Build SMI urgently
A38: DISRUPTIVE CHALLENGER | B38: <5.5 | C38: ≥5.5 | D38: Strong offense, weak defense | E38: Tesla 2015-19 | F38: Shore up RI
A39: DOUBLE EXPOSURE | B39: <5.5 | C39: <5.5 | D39: Vulnerable both | E39: Kodak 2000s | F39: Emergency restructure

Sheet Objectives
A1: =FALSE() -> FALSE
C3: =IF(SelectedBU="","",INDEX(ReportingUnits,SelectedBU,1)) -> Company 3 | G3: Objectives
C7: Time Horizon:
C8: What is the timeframe for which risks and opportunities have been identified and likelihood of occurrence is defined? | G8: 3
C11: List of the main objectives taken into consideration to identify the priority risks and opportunities
C13: Objectives (Priority Issues, Orientation Letter, etc) | D13: Strategic Priorities | E13: Operational performance | F13: License to operate | G13: Measures / Targets (Budget, Financial Figures, etc)
C43: =COUNTA(C$14:C42) -> 0
C44: Stakeholders interests (Corporate responsibility) have been considered to identify the risks

Sheet Risk Thresholds
C3: =IF(SelectedBU="","",INDEX(ReportingUnits,SelectedBU,1)) -> Company 3 | J3: Risk Scale Matrix
C6: Financial Impact Scale
F7: Loss of Cash Flow | K7: Probability Scale | M7: P Scale | N7: PMín | O7: PMáx
C8: As-planned Scenario (Base Case) = 12 months FCF target | E8: Negligible | F8: Minor | G8: Moderate | H8: Major | I8: Critical | M8: 1 | N8: 0 | O8: 0.1
E9: ="up to "&FIXED(E10,0,FALSE())&" mio USD" -> up to 2 mio USD | F9: ="from "&FIXED(E10,0,FALSE())&" to "&FIXED(F10,0,FALSE())&" mio USD" -> from 2 to 5 mio USD | G9: ="from "&FIXED(F10,0,FALSE())&" to "&FIXED(G10,0,FALSE())&" mio USD" -> from 5 to 10 mio USD | H9: ="from "&FIXED(G10,0,FALSE())&" to "&FIXED(H10,0,FALSE())&" mio USD" -> from 10 to 30 mio USD | I9: ="above "&FIXED(MatrixImpact!I13,0,FALSE())&" mio USD" -> above 30 mio USD | M9: 2 | N9: =O8 -> 0.1 | O9: 0.3
E10: =MatrixImpact!I10 -> 2 | F10: =MatrixImpact!I11 -> 5 | G10: =MatrixImpact!I12 -> 10 | H10: =MatrixImpact!I13 -> 30 | I10: 30 | J10: =IFERROR("= "&TEXT(I10/C9,"0.0%")&" base case","") | M10: 3 | N10: =O9 -> 0.3 | O10: 0.5
M11: 4 | N11: =O10 -> 0.5 | O11: 0.9
M12: 5 | N12: =O11 -> 0.9 | O12: 1
E13: Financial
F14: Maximum
F15: Catastrophic
E16: =FIXED(MatrixImpact!I13,0,FALSE())&" mio Euro" -> 30 mio Euro | F16: 5) Critical
E17: =G10 -> 10 | F17: 4) Major
E18: =F10 -> 5 | F18: 3) Moderate
E19: =E10 -> 2 | F19: 2) Minor
E20: 0 | F20: 1) Negligible | G20: =MatrixImpact!C4 -> 0 | H20: =MatrixImpact!C5 -> 0.1 | I20: =MatrixImpact!C6 -> 0.3 | J20: =MatrixImpact!C7 -> 0.5 | K20: =MatrixImpact!C8 -> 0.9 | L20: 1
G21: ="1: Rare: very unlikely to occur during the "&Parameters!E17 -> 1: Rare: very unlikely to occur during the next 3 - 5 years | H21: ="2: Not impossible to occur during the "&Parameters!E17 -> 2: Not impossible to occur during the next 3 - 5 years | I21: ="3: Possible: can be expected at least once in the "&Parameters!E17 -> 3: Possible: can be expected at least once in the next 3 - 5 years | J21: ="4: Likely to arise once during the "&Parameters!E17 -> 4: Likely to arise once during the next 3 - 5 years | K21: ="5: Almost certain: will occur several times during the "&Parameters!E17 -> 5: Almost certain: will occur several times during the next 3 - 5 years
C22: Non-Financial Impacts
D24: 1) Negligible | F24: 2) Minor | H24: 3) Moderate | J24: 4) Major | L24: 5) Critical
C25: Damage to physical integrity of the people | D25: - Person requires first aid treatment (eg cold compress, band aid etc) | F25: - Person requires medical treatment (such as prescribed medication, stitches or sutures etc) | H25: - Person is unable to perform all normal duties (modified or restricted work) | J25: - Single fatality or permanently disabling injury or illness (such as amputation, noise induced hearing loss, etc.) | L25: - Multiple fatalities of and/or extensive health impact on staff, contractors or public
C26: Loss of motivation & Degradation of social climate | D26: - Degradation of professional climate without impact on productivity | F26: - Temporary decrease in employee productivity | H26: - Long lasting decrease in employee productivity - Abnormally high staff turnover | J26: - Some key executives leave the group - Social conflict causing the interruption of the activity | L26: - A large number of key executives leave the group - Social conflict causing a long term stoppage of the activity
C27: Personal Liability (civil or criminal) for company executive | D27: - No personal liability | F27: - Subpoena - Police investigation | H27: - Financial penalty - Police custody | J27: - Suspended jail sentence for Employees or Executive - Loss of civil rights | L27: - Jail for employees, executive or directors
C28: Environmental | D28: - Environmental incident requiring information of public authorities | F28: - Environmental incident with limited action required | H28: - Environmental harm with medium term recovery (> 5 years) and/or requiring moderate rectification | J28: - Environmental harm with long term recovery (>10 years) and/or requiring significant rectification | L28: - Catastrophic and/or irreversible environmental harm
C29: Image | D29: - Minimal impact on reputation | F29: - Intra-industry knowledge of incident without media attention | H29: - Adverse local media coverage - Concerns on performance by financial analysts or shareholders | J29: - Adverse national media coverage - Significant decrease of shareholder support - Poor reputation as an employer | L29: - Adverse global media coverage - Major loss of shareholder support - Major boycott campaign

Sheet Top 10 Risks
C3: =IF(SelectedBU="","",INDEX(ReportingUnits,SelectedBU,1)) -> Company 3 | H3: ="Top 10 Risks that could occur within the "&Parameters!E17 -> Top 10 Risks that could occur within the next 3 - 5 years
C6: RikId | D6: Risk Title (with a light description) | E6: Causes and Factors (risk main causes and/or factors) | F6: Risk Owner | H6: Risk Assessment | K6: Future Direction (next quarter) | L6: Risk Management Plans | N6: ="Explanatory Comments as compared to the previous Quarterly reporting" -> Explanatory Comments as compared to the previous Quarterly reporting
F7: Name | G7: Function | H7: Impact | J7: Likelihood (Probability) | L7: Commitment to Additional Actions | M7: Due Date
H8: Financial | I8: Non-Financial
C9: 1
C10: 2
C11: 3
C12: 4
C13: 5
C14: 6
C15: 7
C16: 8
C17: 9
C18: 10
C19: 11
C20: 12
... C58: 50
D59: =COUNTA(D9:D58) -> 0 | E59: =COUNTA(E9:E58) -> 0 | F59: =COUNTA(F9:F58) -> 0 | G59: =COUNTA(G9:G58) -> 0

Sheet Top 10 Risks (Page 2)
C3: =IF(SelectedBU="","",INDEX(ReportingUnits,SelectedBU,1)) -> Company 3 | J3: ="Top 10 Risks that could occur within the "&Parameters!E17 -> Top 10 Risks that could occur within the next 3 - 5 years
C6: RiskId | D6: Risk Title (with a light description) | E6: Risk Response | F6: Who should know about the Risk? (outside the reporting unit) | H6: Who should know about mitigations? (outside the reporting unit) | J6: Assurance Providers | L6: Uncertainty about Financial Impact | O6: Financial Impact on MRF | P6: Details of the Calculation | Q6: Targeted Level of risks after implementation of mitigations
F7: Name | G7: Function | H7: Name | I7: Function | J7: Name | K7: Function | L7: Best case | M7: Most Credible | N7: Worst Case | Q7: Targeted Probability | R7: Targeted Impact
C9: =INDIRECT(ADDRESS(ROW(),COLUMN(),1,1,"Top 10 Risks")) -> 1 | D9: =INDIRECT(ADDRESS(ROW(),COLUMN(),1,1,"Top 10 Risks")) -> 0 | M9: =INDIRECT(ADDRESS(ROW(),8,1,1,"Top 10 Risks")) -> 0
C10: =INDIRECT(ADDRESS(ROW(),COLUMN(),1,1,"Top 10 Risks")) -> 2 | D10: =INDIRECT(ADDRESS(ROW(),COLUMN(),1,1,"Top 10 Risks")) -> 0 | M10: =INDIRECT(ADDRESS(ROW(),8,1,1,"Top 10 Risks")) -> 0
C11: =INDIRECT(ADDRESS(ROW(),COLUMN(),1,1,"Top 10 Risks")) -> 3 | D11: =INDIRECT(ADDRESS(ROW(),COLUMN(),1,1,"Top 10 Risks")) -> 0 | M11: =INDIRECT(ADDRESS(ROW(),8,1,1,"Top 10 Risks")) -> 0
C12: =INDIRECT(ADDRESS(ROW(),COLUMN(),1,1,"Top 10 Risks")) -> 4 | D12: =INDIRECT(ADDRESS(ROW(),COLUMN(),1,1,"Top 10 Risks")) -> 0 | M12: =INDIRECT(ADDRESS(ROW(),8,1,1,"Top 10 Risks")) -> 0
C13: =INDIRECT(ADDRESS(ROW(),COLUMN(),1,1,"Top 10 Risks")) -> 5 | D13: =INDIRECT(ADDRESS(ROW(),COLUMN(),1,1,"Top 10 Risks")) -> 0 | M13: =INDIRECT(ADDRESS(ROW(),8,1,1,"Top 10 Risks")) -> 0
C14: =INDIRECT(ADDRESS(ROW(),COLUMN(),1,1,"Top 10 Risks")) -> 6 | D14: =INDIRECT(ADDRESS(ROW(),COLUMN(),1,1,"Top 10 Risks")) -> 0 | M14: =INDIRECT(ADDRESS(ROW(),8,1,1,"Top 10 Risks")) -> 0
C15: =INDIRECT(ADDRESS(ROW(),COLUMN(),1,1,"Top 10 Risks")) -> 7 | D15: =INDIRECT(ADDRESS(ROW(),COLUMN(),1,1,"Top 10 Risks")) -> 0 | M15: =INDIRECT(ADDRESS(ROW(),8,1,1,"Top 10 Risks")) -> 0
C16: =INDIRECT(ADDRESS(ROW(),COLUMN(),1,1,"Top 10 Risks")) -> 8 | D16: =INDIRECT(ADDRESS(ROW(),COLUMN(),1,1,"Top 10 Risks")) -> 0 | M16: =INDIRECT(ADDRESS(ROW(),8,1,1,"Top 10 Risks")) -> 0
C17: =INDIRECT(ADDRESS(ROW(),COLUMN(),1,1,"Top 10 Risks")) -> 9 | D17: =INDIRECT(ADDRESS(ROW(),COLUMN(),1,1,"Top 10 Risks")) -> 0 | M17: =INDIRECT(ADDRESS(ROW(),8,1,1,"Top 10 Risks")) -> 0
C18: =INDIRECT(ADDRESS(ROW(),COLUMN(),1,1,"Top 10 Risks")) -> 10 | D18: =INDIRECT(ADDRESS(ROW(),COLUMN(),1,1,"Top 10 Risks")) -> 0 | M18: =INDIRECT(ADDRESS(ROW(),8,1,1,"Top 10 Risks")) -> 0
C19: =INDIRECT(ADDRESS(ROW(),COLUMN(),1,1,"Top 10 Risks")) -> 11 | D19: =INDIRECT(ADDRESS(ROW(),COLUMN(),1,1,"Top 10 Risks")) -> 0 | M19: =INDIRECT(ADDRESS(ROW(),8,1,1,"Top 10 Risks")) -> 0
C20: =INDIRECT(ADDRESS(ROW(),COLUMN(),1,1,"Top 10 Risks")) -> 12 | D20: =INDIRECT(ADDRESS(ROW(),COLUMN(),1,1,"Top 10 Risks")) -> 0 | M20: =INDIRECT(ADDRESS(ROW(),8,1,1,"Top 10 Risks")) -> 0
... C58: =INDIRECT(ADDRESS(ROW(),COLUMN(),1,1,"Top 10 Risks")) -> 50 | D58: =INDIRECT(ADDRESS(ROW(),COLUMN(),1,1,"Top 10 Risks")) -> 0 | M58: =INDIRECT(ADDRESS(ROW(),8,1,1,"Top 10 Risks")) -> 0
D59: =COUNTA(D9:D58)-COUNTIF(D9:D58,"") -> 50 | E59: =COUNTA(E9:E58) -> 0 | J59: =COUNTA(J9:J58) -> 0 | K59: =COUNTA(K9:K58) -> 0

Sheet RADAR
A1: RADAR — Risk Assessment Detection & Alert Register (v6.1 Full Calculation Chain)
A2: Each column = one verifiable calculation step | Blue = Input | Black = Formula | Green = Cross-sheet reference
A3: IDENTIFICATION | D3: RISK QUANTIFICATION | H3: VELOCITY & LORENTZ | K3: TIME & EARLY WARNING | P3: PHASE DIAGNOSTICS | R3: ENTROPY & URGENCY | U3: PALMER NOISE & MC BOUNDS | Y3: CLASSIFICATION & NOTES
D4: Input (0-1) | E4: Input | F4: MIN(10,MAX(1, 2×LN(€M+1))) | G4: Prob × Impact | H4: Input (1-10) | I4: H / Calib!C21 | J4: 1/√(1- MIN(v/v,0.95)²) | K4: (10-Vel)×3 | L4: Input (0-1) | M4: Input (0-1) | N4: TTS×Φ×C | O4: EW-TTS / γ | P4: MIN(1,MAX(0, (10-LEW)/10)) | Q4: 1 - PI | R4: Coh_Den!D16 | S4: S / S_max | T4: PI × γ × (2-S_ratio) | U4: η₀+0.3× (1-Freedom) | V4: LEW×(1- 1.645×η) | W4: LEW-TTS | X4: LEW×(1+ 1.645×η) | Y4: Based on Urgency Idx | Z4: Input | AA4: Input
A5: ID | B5: Risk Name | C5: Category | D5: Prob | E5: Impact (€M) | F5: Impact Score | G5: Exp Loss (€M) | H5: Velocity | I5: v / v_max | J5: Lorentz Factor γ | K5: TTS (months) | L5: Phase Prox | M5: Coh Factor | N5: EW-TTS | O5: Lorentz EW-TTS | P5: Phase Index | Q5: Freedom Index | R5: Entropy S | S5: Entropy Ratio | T5: Urgency Index | U5: Palmer Noise η | V5: MC P10 | W5: MC P50 | X5: MC P90 | Y5: Priority | Z5: Signal Str | AA5: Det Conf | AB5: Notes
A6: =IF('Top 10 Risks'!D9="","",'Top 10 Risks'!C9) | B6: =IF('Top 10 Risks'!D9="","",'Top 10 Risks'!D9) | C6: OPS | D6: =IF('Top 10 Risks'!D9="","",IF('Top 10 Risks'!J9=1,0.05,IF('Top 10 Risks'!J9=2,0.2,IF('Top 10 Risks'!J9=3,0.4,IF('Top 10 Risks'!J9=4,0.7,IF('Top 10 Risks'!J9=5,0.95,"")))))) | E6: =IF('Top 10 Risks'!D9="","",IF('Top 10 Risks'!H9=1,MatrixImpact!I10/2,IF('Top 10 Risks'!H9=2,SQRT(MatrixImpact!I10*MatrixImpact!I11),IF('Top 10 Risks'!H9=3,SQRT(MatrixImpact!I11*MatrixImpact!I12),IF('Top 10 Risks'!H9=4,SQRT(MatrixImpact!I12*MatrixImpact!I13),IF('Top 10 Risks'!H9=5,MatrixImpact!I13*1.5,"")))))) | F6: =IF(E6="","",MIN(10,MAX(1,2*LN(E6+1)))) | G6: =IF(D6="","",D6*E6) | H6: =IF('Top 10 Risks'!D9="","",IF('Top 10 Risks'!K9=1,7,IF('Top 10 Risks'!K9=2,5,IF('Top 10 Risks'!K9=3,3,IF('Top 10 Risks'!K9=4,9,5))))) | I6: =IF(H6="","",H6/Calibration!$C$21) | J6: =IF(I6="","",1/SQRT(1-MIN(I6,0.95)^2)) | K6: =IF(H6="","",(10-H6)*3) | L6: =IF(D6="","",MIN(0.95,D6*1.2)) | M6: =IF('Top 10 Risks'!D9="","",MIN(1,SUM('Risk Interaction Map'!E8:AI8)/MAX(1,COUNTA('Top 10 Risks'!D$9:D$39)-1))) | N6: =IF(K6="","",K6*L6*M6) | O6: =IF(N6="","",N6/J6) | P6: =IF(O6="","",MIN(1,MAX(0,(10-O6)/10))) | Q6: =IF(P6="","",1-P6) | R6: =Coherence_Density!$D$16 -> 1.0199813 | S6: =Coherence_Density!$D$18 -> 0.63375 | T6: =IF(P6="","",P6*J6*(2-S6)) | U6: =IF(Q6="","",Calibration!$C$20+0.3*(1-Q6)) | V6: =IF(O6="","",O6*(1-1.645*U6)) | W6: =IF(O6="","",O6) | X6: =IF(O6="","",O6*(1+1.645*U6)) | Y6: =IF(T6="","",IF(T6>=1.5,"CRITICAL",IF(T6>=1,"HIGH",IF(T6>=0.5,"MEDIUM","LOW")))) | Z6: 0.78 | AA6: 0.85 | AB6: =IF('Top 10 Risks'!E9="","",'Top 10 Risks'!E9)
A7: =IF('Top 10 Risks'!D10="","",'Top 10 Risks'!C10) | B7: =IF('Top 10 Risks'!D10="","",'Top 10 Risks'!D10) | C7: REG | D7: =IF('Top 10 Risks'!D10="","",IF('Top 10 Risks'!J10=1,0.05,IF('Top 10 Risks'!J10=2,0.2,IF('Top 10 Risks'!J10=3,0.4,IF('Top 10 Risks'!J10=4,0.7,IF('Top 10 Risks'!J10=5,0.95,"")))))) | E7: =IF('Top 10 Risks'!D10="","",IF('Top 10 Risks'!H10=1,MatrixImpact!I10/2,IF('Top 10 Risks'!H10=2,SQRT(MatrixImpact!I10*MatrixImpact!I11),IF('Top 10 Risks'!H10=3,SQRT(MatrixImpact!I11*MatrixImpact!I12),IF('Top 10 Risks'!H10=4,SQRT(MatrixImpact!I12*MatrixImpact!I13),IF('Top 10 Risks'!H10=5,MatrixImpact!I13*1.5,"")))))) | F7: =IF(E7="","",MIN(10,MAX(1,2*LN(E7+1)))) | G7: =IF(D7="","",D7*E7) | H7: =IF('Top 10 Risks'!D10="","",IF('Top 10 Risks'!K10=1,7,IF('Top 10 Risks'!K10=2,5,IF('Top 10 Risks'!K10=3,3,IF('Top 10 Risks'!K10=4,9,5))))) | I7: =IF(H7="","",H7/Calibration!$C$21) | J7: =IF(I7="","",1/SQRT(1-MIN(I7,0.95)^2)) | K7: =IF(H7="","",(10-H7)*3) | L7: =IF(D7="","",MIN(0.95,D7*1.2)) | M7: =IF('Top 10 Risks'!D10="","",MIN(1,SUM('Risk Interaction Map'!E9:AI9)/MAX(1,COUNTA('Top 10 Risks'!D$9:D$39)-1))) | N7: =IF(K7="","",K7*L7*M7) | O7: =IF(N7="","",N7/J7) | P7: =IF(O7="","",MIN(1,MAX(0,(10-O7)/10))) | Q7: =IF(P7="","",1-P7) | R7: =Coherence_Density!$D$16 -> 1.0199813 | S7: =Coherence_Density!$D$18 -> 0.63375 | T7: =IF(P7="","",P7*J7*(2-S7)) | U7: =IF(Q7="","",Calibration!$C$20+0.3*(1-Q7)) | V7: =IF(O7="","",O7*(1-1.645*U7)) | W7: =IF(O7="","",O7) | X7: =IF(O7="","",O7*(1+1.645*U7)) | Y7: =IF(T7="","",IF(T7>=1.5,"CRITICAL",IF(T7>=1,"HIGH",IF(T7>=0.5,"MEDIUM","LOW")))) | Z7: 0.65 | AA7: 0.8 | AB7: =IF('Top 10 Risks'!E10="","",'Top 10 Risks'!E10)
A8: =IF('Top 10 Risks'!D11="","",'Top 10 Risks'!C11) | B8: =IF('Top 10 Risks'!D11="","",'Top 10 Risks'!D11) | C8: TECH | D8: =IF('Top 10 Risks'!D11="","",IF('Top 10 Risks'!J11=1,0.05,IF('Top 10 Risks'!J11=2,0.2,IF('Top 10 Risks'!J11=3,0.4,IF('Top 10 Risks'!J11=4,0.7,IF('Top 10 Risks'!J11=5,0.95,"")))))) | E8: =IF('Top 10 Risks'!D11="","",IF('Top 10 Risks'!H11=1,MatrixImpact!I10/2,IF('Top 10 Risks'!H11=2,SQRT(MatrixImpact!I10*MatrixImpact!I11),IF('Top 10 Risks'!H11=3,SQRT(MatrixImpact!I11*MatrixImpact!I12),IF('Top 10 Risks'!H11=4,SQRT(MatrixImpact!I12*MatrixImpact!I13),IF('Top 10 Risks'!H11=5,MatrixImpact!I13*1.5,"")))))) | F8: =IF(E8="","",MIN(10,MAX(1,2*LN(E8+1)))) | G8: =IF(D8="","",D8*E8) | H8: =IF('Top 10 Risks'!D11="","",IF('Top 10 Risks'!K11=1,7,IF('Top 10 Risks'!K11=2,5,IF('Top 10 Risks'!K11=3,3,IF('Top 10 Risks'!K11=4,9,5))))) | I8: =IF(H8="","",H8/Calibration!$C$21) | J8: =IF(I8="","",1/SQRT(1-MIN(I8,0.95)^2)) | K8: =IF(H8="","",(10-H8)*3) | L8: =IF(D8="","",MIN(0.95,D8*1.2)) | M8: =IF('Top 10 Risks'!D11="","",MIN(1,SUM('Risk Interaction Map'!E10:AI10)/MAX(1,COUNTA('Top 10 Risks'!D$9:D$39)-1))) | N8: =IF(K8="","",K8*L8*M8) | O8: =IF(N8="","",N8/J8) | P8: =IF(O8="","",MIN(1,MAX(0,(10-O8)/10))) | Q8: =IF(P8="","",1-P8) | R8: =Coherence_Density!$D$16 -> 1.0199813 | S8: =Coherence_Density!$D$18 -> 0.63375 | T8: =IF(P8="","",P8*J8*(2-S8)) | U8: =IF(Q8="","",Calibration!$C$20+0.3*(1-Q8)) | V8: =IF(O8="","",O8*(1-1.645*U8)) | W8: =IF(O8="","",O8) | X8: =IF(O8="","",O8*(1+1.645*U8)) | Y8: =IF(T8="","",IF(T8>=1.5,"CRITICAL",IF(T8>=1,"HIGH",IF(T8>=0.5,"MEDIUM","LOW")))) | Z8: 0.82 | AA8: 0.9 | AB8: =IF('Top 10 Risks'!E11="","",'Top 10 Risks'!E11)
A9: =IF('Top 10 Risks'!D12="","",'Top 10 Risks'!C12) | B9: =IF('Top 10 Risks'!D12="","",'Top 10 Risks'!D12) | D9: =IF('Top 10 Risks'!D12="","",IF('Top 10 Risks'!J12=1,0.05,IF('Top 10 Risks'!J12=2,0.2,IF('Top 10 Risks'!J12=3,0.4,IF('Top 10 Risks'!J12=4,0.7,IF('Top 10 Risks'!J12=5,0.95,"")))))) | E9: =IF('Top 10 Risks'!D12="","",IF('Top 10 Risks'!H12=1,MatrixImpact!I10/2,IF('Top 10 Risks'!H12=2,SQRT(MatrixImpact!I10*MatrixImpact!I11),IF('Top 10 Risks'!H12=3,SQRT(MatrixImpact!I11*MatrixImpact!I12),IF('Top 10 Risks'!H12=4,SQRT(MatrixImpact!I12*MatrixImpact!I13),IF('Top 10 Risks'!H12=5,MatrixImpact!I13*1.5,"")))))) | F9: =IF(E9="","",MIN(10,MAX(1,2*LN(E9+1)))) | G9: =IF(D9="","",D9*E9) | H9: =IF('Top 10 Risks'!D12="","",IF('Top 10 Risks'!K12=1,7,IF('Top 10 Risks'!K12=2,5,IF('Top 10 Risks'!K12=3,3,IF('Top 10 Risks'!K12=4,9,5))))) | I9: =IF(H9="","",H9/Calibration!$C$21) | J9: =IF(I9="","",1/SQRT(1-MIN(I9,0.95)^2)) | K9: =IF(H9="","",(10-H9)*3) | L9: =IF(D9="","",MIN(0.95,D9*1.2)) | M9: =IF('Top 10 Risks'!D12="","",MIN(1,SUM('Risk Interaction Map'!E11:AI11)/MAX(1,COUNTA('Top 10 Risks'!D$9:D$39)-1))) | N9: =IF(K9="","",K9*L9*M9) | O9: =IF(N9="","",N9/J9) | P9: =IF(O9="","",MIN(1,MAX(0,(10-O9)/10))) | Q9: =IF(P9="","",1-P9) | R9: =Coherence_Density!$D$16 -> 1.0199813 | S9: =Coherence_Density!$D$18 -> 0.63375 | T9: =IF(P9="","",P9*J9*(2-S9)) | U9: =IF(Q9="","",Calibration!$C$20+0.3*(1-Q9)) | V9: =IF(O9="","",O9*(1-1.645*U9)) | W9: =IF(O9="","",O9) | X9: =IF(O9="","",O9*(1+1.645*U9)) | Y9: =IF(T9="","",IF(T9>=1.5,"CRITICAL",IF(T9>=1,"HIGH",IF(T9>=0.5,"MEDIUM","LOW")))) | AB9: =IF('Top 10 Risks'!E12="","",'Top 10 Risks'!E12)
A10: =IF('Top 10 Risks'!D13="","",'Top 10 Risks'!C13) | B10: =IF('Top 10 Risks'!D13="","",'Top 10 Risks'!D13) | D10: =IF('Top 10 Risks'!D13="","",IF('Top 10 Risks'!J13=1,0.05,IF('Top 10 Risks'!J13=2,0.2,IF('Top 10 Risks'!J13=3,0.4,IF('Top 10 Risks'!J13=4,0.7,IF('Top 10 Risks'!J13=5,0.95,"")))))) | E10: =IF('Top 10 Risks'!D13="","",IF('Top 10 Risks'!H13=1,MatrixImpact!I10/2,IF('Top 10 Risks'!H13=2,SQRT(MatrixImpact!I10*MatrixImpact!I11),IF('Top 10 Risks'!H13=3,SQRT(MatrixImpact!I11*MatrixImpact!I12),IF('Top 10 Risks'!H13=4,SQRT(MatrixImpact!I12*MatrixImpact!I13),IF('Top 10 Risks'!H13=5,MatrixImpact!I13*1.5,"")))))) | F10: =IF(E10="","",MIN(10,MAX(1,2*LN(E10+1)))) | G10: =IF(D10="","",D10*E10) | H10: =IF('Top 10 Risks'!D13="","",IF('Top 10 Risks'!K13=1,7,IF('Top 10 Risks'!K13=2,5,IF('Top 10 Risks'!K13=3,3,IF('Top 10 Risks'!K13=4,9,5))))) | I10: =IF(H10="","",H10/Calibration!$C$21) | J10: =IF(I10="","",1/SQRT(1-MIN(I10,0.95)^2)) | K10: =IF(H10="","",(10-H10)*3) | L10: =IF(D10="","",MIN(0.95,D10*1.2)) | M10: =IF('Top 10 Risks'!D13="","",MIN(1,SUM('Risk Interaction Map'!E12:AI12)/MAX(1,COUNTA('Top 10 Risks'!D$9:D$39)-1))) | N10: =IF(K10="","",K10*L10*M10) | O10: =IF(N10="","",N10/J10) | P10: =IF(O10="","",MIN(1,MAX(0,(10-O10)/10))) | Q10: =IF(P10="","",1-P10) | R10: =Coherence_Density!$D$16 -> 1.0199813 | S10: =Coherence_Density!$D$18 -> 0.63375 | T10: =IF(P10="","",P10*J10*(2-S10)) | U10: =IF(Q10="","",Calibration!$C$20+0.3*(1-Q10)) | V10: =IF(O10="","",O10*(1-1.645*U10)) | W10: =IF(O10="","",O10) | X10: =IF(O10="","",O10*(1+1.645*U10)) | Y10: =IF(T10="","",IF(T10>=1.5,"CRITICAL",IF(T10>=1,"HIGH",IF(T10>=0.5,"MEDIUM","LOW")))) | AB10: =IF('Top 10 Risks'!E13="","",'Top 10 Risks'!E13)
A11: =IF('Top 10 Risks'!D14="","",'Top 10 Risks'!C14) | B11: =IF('Top 10 Risks'!D14="","",'Top 10 Risks'!D14) | D11: =IF('Top 10 Risks'!D14="","",IF('Top 10 Risks'!J14=1,0.05,IF('Top 10 Risks'!J14=2,0.2,IF('Top 10 Risks'!J14=3,0.4,IF('Top 10 Risks'!J14=4,0.7,IF('Top 10 Risks'!J14=5,0.95,"")))))) | E11: =IF('Top 10 Risks'!D14="","",IF('Top 10 Risks'!H14=1,MatrixImpact!I10/2,IF('Top 10 Risks'!H14=2,SQRT(MatrixImpact!I10*MatrixImpact!I11),IF('Top 10 Risks'!H14=3,SQRT(MatrixImpact!I11*MatrixImpact!I12),IF('Top 10 Risks'!H14=4,SQRT(MatrixImpact!I12*MatrixImpact!I13),IF('Top 10 Risks'!H14=5,MatrixImpact!I13*1.5,"")))))) | F11: =IF(E11="","",MIN(10,MAX(1,2*LN(E11+1)))) | G11: =IF(D11="","",D11*E11) | H11: =IF('Top 10 Risks'!D14="","",IF('Top 10 Risks'!K14=1,7,IF('Top 10 Risks'!K14=2,5,IF('Top 10 Risks'!K14=3,3,IF('Top 10 Risks'!K14=4,9,5))))) | I11: =IF(H11="","",H11/Calibration!$C$21) | J11: =IF(I11="","",1/SQRT(1-MIN(I11,0.95)^2)) | K11: =IF(H11="","",(10-H11)*3) | L11: =IF(D11="","",MIN(0.95,D11*1.2)) | M11: =IF('Top 10 Risks'!D14="","",MIN(1,SUM('Risk Interaction Map'!E13:AI13)/MAX(1,COUNTA('Top 10 Risks'!D$9:D$39)-1))) | N11: =IF(K11="","",K11*L11*M11) | O11: =IF(N11="","",N11/J11) | P11: =IF(O11="","",MIN(1,MAX(0,(10-O11)/10))) | Q11: =IF(P11="","",1-P11) | R11: =Coherence_Density!$D$16 -> 1.0199813 | S11: =Coherence_Density!$D$18 -> 0.63375 | T11: =IF(P11="","",P11*J11*(2-S11)) | U11: =IF(Q11="","",Calibration!$C$20+0.3*(1-Q11)) | V11: =IF(O11="","",O11*(1-1.645*U11)) | W11: =IF(O11="","",O11) | X11: =IF(O11="","",O11*(1+1.645*U11)) | Y11: =IF(T11="","",IF(T11>=1.5,"CRITICAL",IF(T11>=1,"HIGH",IF(T11>=0.5,"MEDIUM","LOW")))) | AB11: =IF('Top 10 Risks'!E14="","",'Top 10 Risks'!E14)
A12: =IF('Top 10 Risks'!D15="","",'Top 10 Risks'!C15) | B12: =IF('Top 10 Risks'!D15="","",'Top 10 Risks'!D15) | D12: =IF('Top 10 Risks'!D15="","",IF('Top 10 Risks'!J15=1,0.05,IF('Top 10 Risks'!J15=2,0.2,IF('Top 10 Risks'!J15=3,0.4,IF('Top 10 Risks'!J15=4,0.7,IF('Top 10 Risks'!J15=5,0.95,"")))))) | E12: =IF('Top 10 Risks'!D15="","",IF('Top 10 Risks'!H15=1,MatrixImpact!I10/2,IF('Top 10 Risks'!H15=2,SQRT(MatrixImpact!I10*MatrixImpact!I11),IF('Top 10 Risks'!H15=3,SQRT(MatrixImpact!I11*MatrixImpact!I12),IF('Top 10 Risks'!H15=4,SQRT(MatrixImpact!I12*MatrixImpact!I13),IF('Top 10 Risks'!H15=5,MatrixImpact!I13*1.5,"")))))) | F12: =IF(E12="","",MIN(10,MAX(1,2*LN(E12+1)))) | G12: =IF(D12="","",D12*E12) | H12: =IF('Top 10 Risks'!D15="","",IF('Top 10 Risks'!K15=1,7,IF('Top 10 Risks'!K15=2,5,IF('Top 10 Risks'!K15=3,3,IF('Top 10 Risks'!K15=4,9,5))))) | I12: =IF(H12="","",H12/Calibration!$C$21) | J12: =IF(I12="","",1/SQRT(1-MIN(I12,0.95)^2)) | K12: =IF(H12="","",(10-H12)*3) | L12: =IF(D12="","",MIN(0.95,D12*1.2)) | M12: =IF('Top 10 Risks'!D15="","",MIN(1,SUM('Risk Interaction Map'!E14:AI14)/MAX(1,COUNTA('Top 10 Risks'!D$9:D$39)-1))) | N12: =IF(K12="","",K12*L12*M12) | O12: =IF(N12="","",N12/J12) | P12: =IF(O12="","",MIN(1,MAX(0,(10-O12)/10))) | Q12: =IF(P12="","",1-P12) | R12: =Coherence_Density!$D$16 -> 1.0199813 | S12: =Coherence_Density!$D$18 -> 0.63375 | T12: =IF(P12="","",P12*J12*(2-S12)) | U12: =IF(Q12="","",Calibration!$C$20+0.3*(1-Q12)) | V12: =IF(O12="","",O12*(1-1.645*U12)) | W12: =IF(O12="","",O12) | X12: =IF(O12="","",O12*(1+1.645*U12)) | Y12: =IF(T12="","",IF(T12>=1.5,"CRITICAL",IF(T12>=1,"HIGH",IF(T12>=0.5,"MEDIUM","LOW")))) | AB12: =IF('Top 10 Risks'!E15="","",'Top 10 Risks'!E15)
A13: =IF('Top 10 Risks'!D16="","",'Top 10 Risks'!C16) | B13: =IF('Top 10 Risks'!D16="","",'Top 10 Risks'!D16) | D13: =IF('Top 10 Risks'!D16="","",IF('Top 10 Risks'!J16=1,0.05,IF('Top 10 Risks'!J16=2,0.2,IF('Top 10 Risks'!J16=3,0.4,IF('Top 10 Risks'!J16=4,0.7,IF('Top 10 Risks'!J16=5,0.95,"")))))) | E13: =IF('Top 10 Risks'!D16="","",IF('Top 10 Risks'!H16=1,MatrixImpact!I10/2,IF('Top 10 Risks'!H16=2,SQRT(MatrixImpact!I10*MatrixImpact!I11),IF('Top 10 Risks'!H16=3,SQRT(MatrixImpact!I11*MatrixImpact!I12),IF('Top 10 Risks'!H16=4,SQRT(MatrixImpact!I12*MatrixImpact!I13),IF('Top 10 Risks'!H16=5,MatrixImpact!I13*1.5,"")))))) | F13: =IF(E13="","",MIN(10,MAX(1,2*LN(E13+1)))) | G13: =IF(D13="","",D13*E13) | H13: =IF('Top 10 Risks'!D16="","",IF('Top 10 Risks'!K16=1,7,IF('Top 10 Risks'!K16=2,5,IF('Top 10 Risks'!K16=3,3,IF('Top 10 Risks'!K16=4,9,5))))) | I13: =IF(H13="","",H13/Calibration!$C$21) | J13: =IF(I13="","",1/SQRT(1-MIN(I13,0.95)^2)) | K13: =IF(H13="","",(10-H13)*3) | L13: =IF(D13="","",MIN(0.95,D13*1.2)) | M13: =IF('Top 10 Risks'!D16="","",MIN(1,SUM('Risk Interaction Map'!E15:AI15)/MAX(1,COUNTA('Top 10 Risks'!D$9:D$39)-1))) | N13: =IF(K13="","",K13*L13*M13) | O13: =IF(N13="","",N13/J13) | P13: =IF(O13="","",MIN(1,MAX(0,(10-O13)/10))) | Q13: =IF(P13="","",1-P13) | R13: =Coherence_Density!$D$16 -> 1.0199813 | S13: =Coherence_Density!$D$18 -> 0.63375 | T13: =IF(P13="","",P13*J13*(2-S13)) | U13: =IF(Q13="","",Calibration!$C$20+0.3*(1-Q13)) | V13: =IF(O13="","",O13*(1-1.645*U13)) | W13: =IF(O13="","",O13) | X13: =IF(O13="","",O13*(1+1.645*U13)) | Y13: =IF(T13="","",IF(T13>=1.5,"CRITICAL",IF(T13>=1,"HIGH",IF(T13>=0.5,"MEDIUM","LOW")))) | AB13: =IF('Top 10 Risks'!E16="","",'Top 10 Risks'!E16)
A14: =IF('Top 10 Risks'!D17="","",'Top 10 Risks'!C17) | B14: =IF('Top 10 Risks'!D17="","",'Top 10 Risks'!D17) | D14: =IF('Top 10 Risks'!D17="","",IF('Top 10 Risks'!J17=1,0.05,IF('Top 10 Risks'!J17=2,0.2,IF('Top 10 Risks'!J17=3,0.4,IF('Top 10 Risks'!J17=4,0.7,IF('Top 10 Risks'!J17=5,0.95,"")))))) | E14: =IF('Top 10 Risks'!D17="","",IF('Top 10 Risks'!H17=1,MatrixImpact!I10/2,IF('Top 10 Risks'!H17=2,SQRT(MatrixImpact!I10*MatrixImpact!I11),IF('Top 10 Risks'!H17=3,SQRT(MatrixImpact!I11*MatrixImpact!I12),IF('Top 10 Risks'!H17=4,SQRT(MatrixImpact!I12*MatrixImpact!I13),IF('Top 10 Risks'!H17=5,MatrixImpact!I13*1.5,"")))))) | F14: =IF(E14="","",MIN(10,MAX(1,2*LN(E14+1)))) | G14: =IF(D14="","",D14*E14) | H14: =IF('Top 10 Risks'!D17="","",IF('Top 10 Risks'!K17=1,7,IF('Top 10 Risks'!K17=2,5,IF('Top 10 Risks'!K17=3,3,IF('Top 10 Risks'!K17=4,9,5))))) | I14: =IF(H14="","",H14/Calibration!$C$21) | J14: =IF(I14="","",1/SQRT(1-MIN(I14,0.95)^2)) | K14: =IF(H14="","",(10-H14)*3) | L14: =IF(D14="","",MIN(0.95,D14*1.2)) | M14: =IF('Top 10 Risks'!D17="","",MIN(1,SUM('Risk Interaction Map'!E16:AI16)/MAX(1,COUNTA('Top 10 Risks'!D$9:D$39)-1))) | N14: =IF(K14="","",K14*L14*M14) | O14: =IF(N14="","",N14/J14) | P14: =IF(O14="","",MIN(1,MAX(0,(10-O14)/10))) | Q14: =IF(P14="","",1-P14) | R14: =Coherence_Density!$D$16 -> 1.0199813 | S14: =Coherence_Density!$D$18 -> 0.63375 | T14: =IF(P14="","",P14*J14*(2-S14)) | U14: =IF(Q14="","",Calibration!$C$20+0.3*(1-Q14)) | V14: =IF(O14="","",O14*(1-1.645*U14)) | W14: =IF(O14="","",O14) | X14: =IF(O14="","",O14*(1+1.645*U14)) | Y14: =IF(T14="","",IF(T14>=1.5,"CRITICAL",IF(T14>=1,"HIGH",IF(T14>=0.5,"MEDIUM","LOW")))) | AB14: =IF('Top 10 Risks'!E17="","",'Top 10 Risks'!E17)
A15: =IF('Top 10 Risks'!D18="","",'Top 10 Risks'!C18) | B15: =IF('Top 10 Risks'!D18="","",'Top 10 Risks'!D18) | D15: =IF('Top 10 Risks'!D18="","",IF('Top 10 Risks'!J18=1,0.05,IF('Top 10 Risks'!J18=2,0.2,IF('Top 10 Risks'!J18=3,0.4,IF('Top 10 Risks'!J18=4,0.7,IF('Top 10 Risks'!J18=5,0.95,"")))))) | E15: =IF('Top 10 Risks'!D18="","",IF('Top 10 Risks'!H18=1,MatrixImpact!I10/2,IF('Top 10 Risks'!H18=2,SQRT(MatrixImpact!I10*MatrixImpact!I11),IF('Top 10 Risks'!H18=3,SQRT(MatrixImpact!I11*MatrixImpact!I12),IF('Top 10 Risks'!H18=4,SQRT(MatrixImpact!I12*MatrixImpact!I13),IF('Top 10 Risks'!H18=5,MatrixImpact!I13*1.5,"")))))) | F15: =IF(E15="","",MIN(10,MAX(1,2*LN(E15+1)))) | G15: =IF(D15="","",D15*E15) | H15: =IF('Top 10 Risks'!D18="","",IF('Top 10 Risks'!K18=1,7,IF('Top 10 Risks'!K18=2,5,IF('Top 10 Risks'!K18=3,3,IF('Top 10 Risks'!K18=4,9,5))))) | I15: =IF(H15="","",H15/Calibration!$C$21) | J15: =IF(I15="","",1/SQRT(1-MIN(I15,0.95)^2)) | K15: =IF(H15="","",(10-H15)*3) | L15: =IF(D15="","",MIN(0.95,D15*1.2)) | M15: =IF('Top 10 Risks'!D18="","",MIN(1,SUM('Risk Interaction Map'!E17:AI17)/MAX(1,COUNTA('Top 10 Risks'!D$9:D$39)-1))) | N15: =IF(K15="","",K15*L15*M15) | O15: =IF(N15="","",N15/J15) | P15: =IF(O15="","",MIN(1,MAX(0,(10-O15)/10))) | Q15: =IF(P15="","",1-P15) | R15: =Coherence_Density!$D$16 -> 1.0199813 | S15: =Coherence_Density!$D$18 -> 0.63375 | T15: =IF(P15="","",P15*J15*(2-S15)) | U15: =IF(Q15="","",Calibration!$C$20+0.3*(1-Q15)) | V15: =IF(O15="","",O15*(1-1.645*U15)) | W15: =IF(O15="","",O15) | X15: =IF(O15="","",O15*(1+1.645*U15)) | Y15: =IF(T15="","",IF(T15>=1.5,"CRITICAL",IF(T15>=1,"HIGH",IF(T15>=0.5,"MEDIUM","LOW")))) | AB15: =IF('Top 10 Risks'!E18="","",'Top 10 Risks'!E18)
A16: =IF('Top 10 Risks'!D19="","",'Top 10 Risks'!C19) | B16: =IF('Top 10 Risks'!D19="","",'Top 10 Risks'!D19) | D16: =IF('Top 10 Risks'!D19="","",IF('Top 10 Risks'!J19=1,0.05,IF('Top 10 Risks'!J19=2,0.2,IF('Top 10 Risks'!J19=3,0.4,IF('Top 10 Risks'!J19=4,0.7,IF('Top 10 Risks'!J19=5,0.95,"")))))) | E16: =IF('Top 10 Risks'!D19="","",IF('Top 10 Risks'!H19=1,MatrixImpact!I10/2,IF('Top 10 Risks'!H19=2,SQRT(MatrixImpact!I10*MatrixImpact!I11),IF('Top 10 Risks'!H19=3,SQRT(MatrixImpact!I11*MatrixImpact!I12),IF('Top 10 Risks'!H19=4,SQRT(MatrixImpact!I12*MatrixImpact!I13),IF('Top 10 Risks'!H19=5,MatrixImpact!I13*1.5,"")))))) | F16: =IF(E16="","",MIN(10,MAX(1,2*LN(E16+1)))) | G16: =IF(D16="","",D16*E16) | H16: =IF('Top 10 Risks'!D19="","",IF('Top 10 Risks'!K19=1,7,IF('Top 10 Risks'!K19=2,5,IF('Top 10 Risks'!K19=3,3,IF('Top 10 Risks'!K19=4,9,5))))) | I16: =IF(H16="","",H16/Calibration!$C$21) | J16: =IF(I16="","",1/SQRT(1-MIN(I16,0.95)^2)) | K16: =IF(H16="","",(10-H16)*3) | L16: =IF(D16="","",MIN(0.95,D16*1.2)) | M16: =IF('Top 10 Risks'!D19="","",MIN(1,SUM('Risk Interaction Map'!E18:AI18)/MAX(1,COUNTA('Top 10 Risks'!D$9:D$39)-1))) | N16: =IF(K16="","",K16*L16*M16) | O16: =IF(N16="","",N16/J16) | P16: =IF(O16="","",MIN(1,MAX(0,(10-O16)/10))) | Q16: =IF(P16="","",1-P16) | R16: =Coherence_Density!$D$16 -> 1.0199813 | S16: =Coherence_Density!$D$18 -> 0.63375 | T16: =IF(P16="","",P16*J16*(2-S16)) | U16: =IF(Q16="","",Calibration!$C$20+0.3*(1-Q16)) | V16: =IF(O16="","",O16*(1-1.645*U16)) | W16: =IF(O16="","",O16) | X16: =IF(O16="","",O16*(1+1.645*U16)) | Y16: =IF(T16="","",IF(T16>=1.5,"CRITICAL",IF(T16>=1,"HIGH",IF(T16>=0.5,"MEDIUM","LOW")))) | AB16: =IF('Top 10 Risks'!E19="","",'Top 10 Risks'!E19)
A17: =IF('Top 10 Risks'!D20="","",'Top 10 Risks'!C20) | B17: =IF('Top 10 Risks'!D20="","",'Top 10 Risks'!D20) | D17: =IF('Top 10 Risks'!D20="","",IF('Top 10 Risks'!J20=1,0.05,IF('Top 10 Risks'!J20=2,0.2,IF('Top 10 Risks'!J20=3,0.4,IF('Top 10 Risks'!J20=4,0.7,IF('Top 10 Risks'!J20=5,0.95,"")))))) | E17: =IF('Top 10 Risks'!D20="","",IF('Top 10 Risks'!H20=1,MatrixImpact!I10/2,IF('Top 10 Risks'!H20=2,SQRT(MatrixImpact!I10*MatrixImpact!I11),IF('Top 10 Risks'!H20=3,SQRT(MatrixImpact!I11*MatrixImpact!I12),IF('Top 10 Risks'!H20=4,SQRT(MatrixImpact!I12*MatrixImpact!I13),IF('Top 10 Risks'!H20=5,MatrixImpact!I13*1.5,"")))))) | F17: =IF(E17="","",MIN(10,MAX(1,2*LN(E17+1)))) | G17: =IF(D17="","",D17*E17) | H17: =IF('Top 10 Risks'!D20="","",IF('Top 10 Risks'!K20=1,7,IF('Top 10 Risks'!K20=2,5,IF('Top 10 Risks'!K20=3,3,IF('Top 10 Risks'!K20=4,9,5))))) | I17: =IF(H17="","",H17/Calibration!$C$21) | J17: =IF(I17="","",1/SQRT(1-MIN(I17,0.95)^2)) | K17: =IF(H17="","",(10-H17)*3) | L17: =IF(D17="","",MIN(0.95,D17*1.2)) | M17: =IF('Top 10 Risks'!D20="","",MIN(1,SUM('Risk Interaction Map'!E19:AI19)/MAX(1,COUNTA('Top 10 Risks'!D$9:D$39)-1))) | N17: =IF(K17="","",K17*L17*M17) | O17: =IF(N17="","",N17/J17) | P17: =IF(O17="","",MIN(1,MAX(0,(10-O17)/10))) | Q17: =IF(P17="","",1-P17) | R17: =Coherence_Density!$D$16 -> 1.0199813 | S17: =Coherence_Density!$D$18 -> 0.63375 | T17: =IF(P17="","",P17*J17*(2-S17)) | U17: =IF(Q17="","",Calibration!$C$20+0.3*(1-Q17)) | V17: =IF(O17="","",O17*(1-1.645*U17)) | W17: =IF(O17="","",O17) | X17: =IF(O17="","",O17*(1+1.645*U17)) | Y17: =IF(T17="","",IF(T17>=1.5,"CRITICAL",IF(T17>=1,"HIGH",IF(T17>=0.5,"MEDIUM","LOW")))) | AB17: =IF('Top 10 Risks'!E20="","",'Top 10 Risks'!E20)
A18: =IF('Top 10 Risks'!D21="","",'Top 10 Risks'!C21) | B18: =IF('Top 10 Risks'!D21="","",'Top 10 Risks'!D21) | D18: =IF('Top 10 Risks'!D21="","",IF('Top 10 Risks'!J21=1,0.05,IF('Top 10 Risks'!J21=2,0.2,IF('Top 10 Risks'!J21=3,0.4,IF('Top 10 Risks'!J21=4,0.7,IF('Top 10 Risks'!J21=5,0.95,"")))))) | E18: =IF('Top 10 Risks'!D21="","",IF('Top 10 Risks'!H21=1,MatrixImpact!I10/2,IF('Top 10 Risks'!H21=2,SQRT(MatrixImpact!I10*MatrixImpact!I11),IF('Top 10 Risks'!H21=3,SQRT(MatrixImpact!I11*MatrixImpact!I12),IF('Top 10 Risks'!H21=4,SQRT(MatrixImpact!I12*MatrixImpact!I13),IF('Top 10 Risks'!H21=5,MatrixImpact!I13*1.5,"")))))) | F18: =IF(E18="","",MIN(10,MAX(1,2*LN(E18+1)))) | G18: =IF(D18="","",D18*E18) | H18: =IF('Top 10 Risks'!D21="","",IF('Top 10 Risks'!K21=1,7,IF('Top 10 Risks'!K21=2,5,IF('Top 10 Risks'!K21=3,3,IF('Top 10 Risks'!K21=4,9,5))))) | I18: =IF(H18="","",H18/Calibration!$C$21) | J18: =IF(I18="","",1/SQRT(1-MIN(I18,0.95)^2)) | K18: =IF(H18="","",(10-H18)*3) | L18: =IF(D18="","",MIN(0.95,D18*1.2)) | M18: =IF('Top 10 Risks'!D21="","",MIN(1,SUM('Risk Interaction Map'!E20:AI20)/MAX(1,COUNTA('Top 10 Risks'!D$9:D$39)-1))) | N18: =IF(K18="","",K18*L18*M18) | O18: =IF(N18="","",N18/J18) | P18: =IF(O18="","",MIN(1,MAX(0,(10-O18)/10))) | Q18: =IF(P18="","",1-P18) | R18: =Coherence_Density!$D$16 -> 1.0199813 | S18: =Coherence_Density!$D$18 -> 0.63375 | T18: =IF(P18="","",P18*J18*(2-S18)) | U18: =IF(Q18="","",Calibration!$C$20+0.3*(1-Q18)) | V18: =IF(O18="","",O18*(1-1.645*U18)) | W18: =IF(O18="","",O18) | X18: =IF(O18="","",O18*(1+1.645*U18)) | Y18: =IF(T18="","",IF(T18>=1.5,"CRITICAL",IF(T18>=1,"HIGH",IF(T18>=0.5,"MEDIUM","LOW")))) | AB18: =IF('Top 10 Risks'!E21="","",'Top 10 Risks'!E21)
A19: =IF('Top 10 Risks'!D22="","",'Top 10 Risks'!C22) | B19: =IF('Top 10 Risks'!D22="","",'Top 10 Risks'!D22) | D19: =IF('Top 10 Risks'!D22="","",IF('Top 10 Risks'!J22=1,0.05,IF('Top 10 Risks'!J22=2,0.2,IF('Top 10 Risks'!J22=3,0.4,IF('Top 10 Risks'!J22=4,0.7,IF('Top 10 Risks'!J22=5,0.95,"")))))) | E19: =IF('Top 10 Risks'!D22="","",IF('Top 10 Risks'!H22=1,MatrixImpact!I10/2,IF('Top 10 Risks'!H22=2,SQRT(MatrixImpact!I10*MatrixImpact!I11),IF('Top 10 Risks'!H22=3,SQRT(MatrixImpact!I11*MatrixImpact!I12),IF('Top 10 Risks'!H22=4,SQRT(MatrixImpact!I12*MatrixImpact!I13),IF('Top 10 Risks'!H22=5,MatrixImpact!I13*1.5,"")))))) | F19: =IF(E19="","",MIN(10,MAX(1,2*LN(E19+1)))) | G19: =IF(D19="","",D19*E19) | H19: =IF('Top 10 Risks'!D22="","",IF('Top 10 Risks'!K22=1,7,IF('Top 10 Risks'!K22=2,5,IF('Top 10 Risks'!K22=3,3,IF('Top 10 Risks'!K22=4,9,5))))) | I19: =IF(H19="","",H19/Calibration!$C$21) | J19: =IF(I19="","",1/SQRT(1-MIN(I19,0.95)^2)) | K19: =IF(H19="","",(10-H19)*3) | L19: =IF(D19="","",MIN(0.95,D19*1.2)) | M19: =IF('Top 10 Risks'!D22="","",MIN(1,SUM('Risk Interaction Map'!E21:AI21)/MAX(1,COUNTA('Top 10 Risks'!D$9:D$39)-1))) | N19: =IF(K19="","",K19*L19*M19) | O19: =IF(N19="","",N19/J19) | P19: =IF(O19="","",MIN(1,MAX(0,(10-O19)/10))) | Q19: =IF(P19="","",1-P19) | R19: =Coherence_Density!$D$16 -> 1.0199813 | S19: =Coherence_Density!$D$18 -> 0.63375 | T19: =IF(P19="","",P19*J19*(2-S19)) | U19: =IF(Q19="","",Calibration!$C$20+0.3*(1-Q19)) | V19: =IF(O19="","",O19*(1-1.645*U19)) | W19: =IF(O19="","",O19) | X19: =IF(O19="","",O19*(1+1.645*U19)) | Y19: =IF(T19="","",IF(T19>=1.5,"CRITICAL",IF(T19>=1,"HIGH",IF(T19>=0.5,"MEDIUM","LOW")))) | AB19: =IF('Top 10 Risks'!E22="","",'Top 10 Risks'!E22)
A20: =IF('Top 10 Risks'!D23="","",'Top 10 Risks'!C23) | B20: =IF('Top 10 Risks'!D23="","",'Top 10 Risks'!D23) | D20: =IF('Top 10 Risks'!D23="","",IF('Top 10 Risks'!J23=1,0.05,IF('Top 10 Risks'!J23=2,0.2,IF('Top 10 Risks'!J23=3,0.4,IF('Top 10 Risks'!J23=4,0.7,IF('Top 10 Risks'!J23=5,0.95,"")))))) | E20: =IF('Top 10 Risks'!D23="","",IF('Top 10 Risks'!H23=1,MatrixImpact!I10/2,IF('Top 10 Risks'!H23=2,SQRT(MatrixImpact!I10*MatrixImpact!I11),IF('Top 10 Risks'!H23=3,SQRT(MatrixImpact!I11*MatrixImpact!I12),IF('Top 10 Risks'!H23=4,SQRT(MatrixImpact!I12*MatrixImpact!I13),IF('Top 10 Risks'!H23=5,MatrixImpact!I13*1.5,"")))))) | F20: =IF(E20="","",MIN(10,MAX(1,2*LN(E20+1)))) | G20: =IF(D20="","",D20*E20) | H20: =IF('Top 10 Risks'!D23="","",IF('Top 10 Risks'!K23=1,7,IF('Top 10 Risks'!K23=2,5,IF('Top 10 Risks'!K23=3,3,IF('Top 10 Risks'!K23=4,9,5))))) | I20: =IF(H20="","",H20/Calibration!$C$21) | J20: =IF(I20="","",1/SQRT(1-MIN(I20,0.95)^2)) | K20: =IF(H20="","",(10-H20)*3) | L20: =IF(D20="","",MIN(0.95,D20*1.2)) | M20: =IF('Top 10 Risks'!D23="","",MIN(1,SUM('Risk Interaction Map'!E22:AI22)/MAX(1,COUNTA('Top 10 Risks'!D$9:D$39)-1))) | N20: =IF(K20="","",K20*L20*M20) | O20: =IF(N20="","",N20/J20) | P20: =IF(O20="","",MIN(1,MAX(0,(10-O20)/10))) | Q20: =IF(P20="","",1-P20) | R20: =Coherence_Density!$D$16 -> 1.0199813 | S20: =Coherence_Density!$D$18 -> 0.63375 | T20: =IF(P20="","",P20*J20*(2-S20)) | U20: =IF(Q20="","",Calibration!$C$20+0.3*(1-Q20)) | V20: =IF(O20="","",O20*(1-1.645*U20)) | W20: =IF(O20="","",O20) | X20: =IF(O20="","",O20*(1+1.645*U20)) | Y20: =IF(T20="","",IF(T20>=1.5,"CRITICAL",IF(T20>=1,"HIGH",IF(T20>=0.5,"MEDIUM","LOW")))) | AB20: =IF('Top 10 Risks'!E23="","",'Top 10 Risks'!E23)
A21: =IF('Top 10 Risks'!D24="","",'Top 10 Risks'!C24) | B21: =IF('Top 10 Risks'!D24="","",'Top 10 Risks'!D24) | D21: =IF('Top 10 Risks'!D24="","",IF('Top 10 Risks'!J24=1,0.05,IF('Top 10 Risks'!J24=2,0.2,IF('Top 10 Risks'!J24=3,0.4,IF('Top 10 Risks'!J24=4,0.7,IF('Top 10 Risks'!J24=5,0.95,"")))))) | E21: =IF('Top 10 Risks'!D24="","",IF('Top 10 Risks'!H24=1,MatrixImpact!I10/2,IF('Top 10 Risks'!H24=2,SQRT(MatrixImpact!I10*MatrixImpact!I11),IF('Top 10 Risks'!H24=3,SQRT(MatrixImpact!I11*MatrixImpact!I12),IF('Top 10 Risks'!H24=4,SQRT(MatrixImpact!I12*MatrixImpact!I13),IF('Top 10 Risks'!H24=5,MatrixImpact!I13*1.5,"")))))) | F21: =IF(E21="","",MIN(10,MAX(1,2*LN(E21+1)))) | G21: =IF(D21="","",D21*E21) | H21: =IF('Top 10 Risks'!D24="","",IF('Top 10 Risks'!K24=1,7,IF('Top 10 Risks'!K24=2,5,IF('Top 10 Risks'!K24=3,3,IF('Top 10 Risks'!K24=4,9,5))))) | I21: =IF(H21="","",H21/Calibration!$C$21) | J21: =IF(I21="","",1/SQRT(1-MIN(I21,0.95)^2)) | K21: =IF(H21="","",(10-H21)*3) | L21: =IF(D21="","",MIN(0.95,D21*1.2)) | M21: =IF('Top 10 Risks'!D24="","",MIN(1,SUM('Risk Interaction Map'!E23:AI23)/MAX(1,COUNTA('Top 10 Risks'!D$9:D$39)-1))) | N21: =IF(K21="","",K21*L21*M21) | O21: =IF(N21="","",N21/J21) | P21: =IF(O21="","",MIN(1,MAX(0,(10-O21)/10))) | Q21: =IF(P21="","",1-P21) | R21: =Coherence_Density!$D$16 -> 1.0199813 | S21: =Coherence_Density!$D$18 -> 0.63375 | T21: =IF(P21="","",P21*J21*(2-S21)) | U21: =IF(Q21="","",Calibration!$C$20+0.3*(1-Q21)) | V21: =IF(O21="","",O21*(1-1.645*U21)) | W21: =IF(O21="","",O21) | X21: =IF(O21="","",O21*(1+1.645*U21)) | Y21: =IF(T21="","",IF(T21>=1.5,"CRITICAL",IF(T21>=1,"HIGH",IF(T21>=0.5,"MEDIUM","LOW")))) | AB21: =IF('Top 10 Risks'!E24="","",'Top 10 Risks'!E24)
A22: =IF('Top 10 Risks'!D25="","",'Top 10 Risks'!C25) | B22: =IF('Top 10 Risks'!D25="","",'Top 10 Risks'!D25) | D22: =IF('Top 10 Risks'!D25="","",IF('Top 10 Risks'!J25=1,0.05,IF('Top 10 Risks'!J25=2,0.2,IF('Top 10 Risks'!J25=3,0.4,IF('Top 10 Risks'!J25=4,0.7,IF('Top 10 Risks'!J25=5,0.95,"")))))) | E22: =IF('Top 10 Risks'!D25="","",IF('Top 10 Risks'!H25=1,MatrixImpact!I10/2,IF('Top 10 Risks'!H25=2,SQRT(MatrixImpact!I10*MatrixImpact!I11),IF('Top 10 Risks'!H25=3,SQRT(MatrixImpact!I11*MatrixImpact!I12),IF('Top 10 Risks'!H25=4,SQRT(MatrixImpact!I12*MatrixImpact!I13),IF('Top 10 Risks'!H25=5,MatrixImpact!I13*1.5,"")))))) | F22: =IF(E22="","",MIN(10,MAX(1,2*LN(E22+1)))) | G22: =IF(D22="","",D22*E22) | H22: =IF('Top 10 Risks'!D25="","",IF('Top 10 Risks'!K25=1,7,IF('Top 10 Risks'!K25=2,5,IF('Top 10 Risks'!K25=3,3,IF('Top 10 Risks'!K25=4,9,5))))) | I22: =IF(H22="","",H22/Calibration!$C$21) | J22: =IF(I22="","",1/SQRT(1-MIN(I22,0.95)^2)) | K22: =IF(H22="","",(10-H22)*3) | L22: =IF(D22="","",MIN(0.95,D22*1.2)) | M22: =IF('Top 10 Risks'!D25="","",MIN(1,SUM('Risk Interaction Map'!E24:AI24)/MAX(1,COUNTA('Top 10 Risks'!D$9:D$39)-1))) | N22: =IF(K22="","",K22*L22*M22) | O22: =IF(N22="","",N22/J22) | P22: =IF(O22="","",MIN(1,MAX(0,(10-O22)/10))) | Q22: =IF(P22="","",1-P22) | R22: =Coherence_Density!$D$16 -> 1.0199813 | S22: =Coherence_Density!$D$18 -> 0.63375 | T22: =IF(P22="","",P22*J22*(2-S22)) | U22: =IF(Q22="","",Calibration!$C$20+0.3*(1-Q22)) | V22: =IF(O22="","",O22*(1-1.645*U22)) | W22: =IF(O22="","",O22) | X22: =IF(O22="","",O22*(1+1.645*U22)) | Y22: =IF(T22="","",IF(T22>=1.5,"CRITICAL",IF(T22>=1,"HIGH",IF(T22>=0.5,"MEDIUM","LOW")))) | AB22: =IF('Top 10 Risks'!E25="","",'Top 10 Risks'!E25)
A23: =IF('Top 10 Risks'!D26="","",'Top 10 Risks'!C26) | B23: =IF('Top 10 Risks'!D26="","",'Top 10 Risks'!D26) | D23: =IF('Top 10 Risks'!D26="","",IF('Top 10 Risks'!J26=1,0.05,IF('Top 10 Risks'!J26=2,0.2,IF('Top 10 Risks'!J26=3,0.4,IF('Top 10 Risks'!J26=4,0.7,IF('Top 10 Risks'!J26=5,0.95,"")))))) | E23: =IF('Top 10 Risks'!D26="","",IF('Top 10 Risks'!H26=1,MatrixImpact!I10/2,IF('Top 10 Risks'!H26=2,SQRT(MatrixImpact!I10*MatrixImpact!I11),IF('Top 10 Risks'!H26=3,SQRT(MatrixImpact!I11*MatrixImpact!I12),IF('Top 10 Risks'!H26=4,SQRT(MatrixImpact!I12*MatrixImpact!I13),IF('Top 10 Risks'!H26=5,MatrixImpact!I13*1.5,"")))))) | F23: =IF(E23="","",MIN(10,MAX(1,2*LN(E23+1)))) | G23: =IF(D23="","",D23*E23) | H23: =IF('Top 10 Risks'!D26="","",IF('Top 10 Risks'!K26=1,7,IF('Top 10 Risks'!K26=2,5,IF('Top 10 Risks'!K26=3,3,IF('Top 10 Risks'!K26=4,9,5))))) | I23: =IF(H23="","",H23/Calibration!$C$21) | J23: =IF(I23="","",1/SQRT(1-MIN(I23,0.95)^2)) | K23: =IF(H23="","",(10-H23)*3) | L23: =IF(D23="","",MIN(0.95,D23*1.2)) | M23: =IF('Top 10 Risks'!D26="","",MIN(1,SUM('Risk Interaction Map'!E25:AI25)/MAX(1,COUNTA('Top 10 Risks'!D$9:D$39)-1))) | N23: =IF(K23="","",K23*L23*M23) | O23: =IF(N23="","",N23/J23) | P23: =IF(O23="","",MIN(1,MAX(0,(10-O23)/10))) | Q23: =IF(P23="","",1-P23) | R23: =Coherence_Density!$D$16 -> 1.0199813 | S23: =Coherence_Density!$D$18 -> 0.63375 | T23: =IF(P23="","",P23*J23*(2-S23)) | U23: =IF(Q23="","",Calibration!$C$20+0.3*(1-Q23)) | V23: =IF(O23="","",O23*(1-1.645*U23)) | W23: =IF(O23="","",O23) | X23: =IF(O23="","",O23*(1+1.645*U23)) | Y23: =IF(T23="","",IF(T23>=1.5,"CRITICAL",IF(T23>=1,"HIGH",IF(T23>=0.5,"MEDIUM","LOW")))) | AB23: =IF('Top 10 Risks'!E26="","",'Top 10 Risks'!E26)
